results/closing_cross_replay_20190130.log
=== lob_replay: NASDAQ TotalView-ITCH 5.0 day replay ===
run: 2026-09-21 04:29:10 local | cpu: Intel(R) Core(TM) Ultra 7 265H | compiler: g++ 16.1.0
command: lob_replay 01302019.NASDAQ_ITCH50 --symbols AAPL,MSFT,AMZN,GOOGL,FB,INTC,CSCO,NVDA,TSLA,NFLX --at 12:00:00,16:00:00 --cpu 0
source: git commit 5b78e5a29b4570d531f61e207b75775cc5ee948d
file: 01302019.NASDAQ_ITCH50
chunk 268,435,456 bytes | checkpoint every 5,000,000 messages | ladder budget 1,024 MB

[1] pre-scan (untimed, 121.0 s)
  bytes 11,245,883,092 | messages 368,366,634 | trailing bytes 0
  message counts by type:
     A   162,970,455    B           116    C       158,886    D   158,273,361
     E     8,096,995    F     1,725,898    H         8,805    I     3,684,511
     J            62    L       193,769    P     1,326,184    Q        17,430
     R         8,714    S             6    U    27,222,746    V             1
     X     4,669,874    Y         8,821
  bad_length 0 | unknown type 0
  first message 03:03:59.687 | last message 20:05:00.000 (ET, from message timestamps) | timestamps out of order 0
  stock directory: 8,714 'R' messages for 8,713 stock_locates (1 repeated, 0 renamed) | locates with order messages: 8,695
  adds (A, F and the add half of U): 191,919,099 | peak resting orders, whole market: 1,742,866
  add prices that are not whole cents: 718,627 | outside $0.01..$1310.72: 587,096
  sizing (13.4 s): 8,695 books | grid $0.01: 8,323, grid $0.0001: 372 | ladder 1024 MB | band ticks min 64 median 2,048 max 131,072
  adds the chosen ladders cover: 191,722,488 of 191,919,099 (99.898%); the other 196,611 rest in the overflow
  pools 2,276,721 order slots (73 MB) | id maps 6,642,368 slots (106 MB)

  named symbols (Stock Directory, and the 'Q' crosses NASDAQ ran):
  AAPL   locate 14    adds 875,938 | peak resting 42,774 | grid $0.01 | ladder 32,768 ticks from $0.0100
         opening cross 163.2200 x 770,817 shares at 09:30:00.300
         closing cross 165.2500 x 2,340,937 shares at 16:00:00.563
  MSFT   locate 5217  adds 867,658 | peak resting 22,116 | grid $0.01 | ladder 16,384 ticks from $0.0100
         opening cross 104.6200 x 500,581 shares at 09:30:00.148
         closing cross 106.3800 x 2,606,642 shares at 16:00:00.531
  AMZN   locate 381   adds 511,215 | peak resting 39,028 | grid $0.01 | ladder 131,072 ticks from $899.0000
         opening cross 1623.0000 x 42,456 shares at 09:30:00.752
         closing cross 1670.4300 x 183,741 shares at 16:00:00.764
  GOOGL  locate 3420  adds 882,948 | peak resting 8,769 | grid $0.01 | ladder 65,536 ticks from $745.1300
         opening cross 1077.3600 x 14,811 shares at 09:30:00.924
         closing cross 1097.9900 x 116,867 shares at 16:00:00.273
  FB     locate 2728  adds 679,229 | peak resting 20,986 | grid $0.01 | ladder 32,768 ticks from $0.0100
         opening cross 146.2200 x 192,425 shares at 09:30:00.872
         closing cross 150.4200 x 1,017,765 shares at 16:00:00.357
  INTC   locate 4118  adds 609,179 | peak resting 11,853 | grid $0.01 | ladder 8,192 ticks from $0.0100
         opening cross 46.6900 x 353,481 shares at 09:30:00.568
         closing cross 47.5400 x 2,204,287 shares at 16:00:00.003
  CSCO   locate 1718  adds 423,946 | peak resting 7,860 | grid $0.01 | ladder 8,192 ticks from $0.0100
         opening cross 45.9400 x 348,306 shares at 09:30:00.850
         closing cross 46.7100 x 1,937,262 shares at 16:00:00.414
  NVDA   locate 5628  adds 701,052 | peak resting 18,558 | grid $0.01 | ladder 32,768 ticks from $0.0100
         opening cross 134.8000 x 258,932 shares at 09:30:00.880
         closing cross 137.3900 x 335,421 shares at 16:00:00.591
  TSLA   locate 7804  adds 476,612 | peak resting 18,306 | grid $0.01 | ladder 32,768 ticks from $173.5000
         opening cross 300.4500 x 40,304 shares at 09:30:00.619
         closing cross 308.7700 x 74,672 shares at 16:00:00.366
  NFLX   locate 5430  adds 378,077 | peak resting 14,071 | grid $0.01 | ladder 32,768 ticks from $148.0000
         opening cross 332.5000 x 50,682 shares at 09:30:00.866
         closing cross 340.6600 x 298,927 shares at 16:00:00.617

[2] replay | thread pinned to cpu 0
  checkpoint   1 | message     5,000,000 | 07:50:47.762 | resting orders 21,239
  chunk   1 | messages     9,031,559 | book digest c1909233da6bd73d
  checkpoint   2 | message    10,000,000 | 09:29:25.142 | resting orders 340,926
  checkpoint   3 | message    15,000,000 | 09:32:23.480 | resting orders 1,481,028
  chunk   2 | messages    16,693,204 | book digest 35ace202b2372ba5
  checkpoint   4 | message    20,000,000 | 09:36:09.034 | resting orders 1,533,131
  checkpoint   5 | message    25,000,000 | 09:39:49.689 | resting orders 1,556,851
  chunk   3 | messages    25,506,955 | book digest ee12c413e7aec9d7
  checkpoint   6 | message    30,000,000 | 09:43:45.424 | resting orders 1,548,122
  chunk   4 | messages    34,337,226 | book digest e3ebf4f7728624b1
  checkpoint   7 | message    35,000,000 | 09:47:51.598 | resting orders 1,570,457
  checkpoint   8 | message    40,000,000 | 09:52:10.696 | resting orders 1,585,524
  chunk   5 | messages    43,178,307 | book digest c7ce2d3b7d1aef38
  checkpoint   9 | message    45,000,000 | 09:56:54.377 | resting orders 1,589,701
  checkpoint  10 | message    50,000,000 | 10:01:44.569 | resting orders 1,593,422
  chunk   6 | messages    52,020,225 | book digest 768d5e3b4d4aadf7
  checkpoint  11 | message    55,000,000 | 10:06:04.473 | resting orders 1,600,015
  checkpoint  12 | message    60,000,000 | 10:11:06.173 | resting orders 1,605,440
  chunk   7 | messages    60,871,499 | book digest edc89b1c4e7dff5c
  checkpoint  13 | message    65,000,000 | 10:15:56.915 | resting orders 1,612,661
  chunk   8 | messages    69,718,789 | book digest 98297ac800eef764
  checkpoint  14 | message    70,000,000 | 10:21:06.736 | resting orders 1,614,490
  checkpoint  15 | message    75,000,000 | 10:26:57.655 | resting orders 1,615,303
  chunk   9 | messages    78,569,068 | book digest 6d80cf185da2bbdd
  checkpoint  16 | message    80,000,000 | 10:32:45.713 | resting orders 1,613,450
  checkpoint  17 | message    85,000,000 | 10:37:51.130 | resting orders 1,620,864
  chunk  10 | messages    87,416,025 | book digest f3b833d52eb39d77
  checkpoint  18 | message    90,000,000 | 10:43:20.184 | resting orders 1,626,686
  checkpoint  19 | message    95,000,000 | 10:49:09.141 | resting orders 1,629,107
  chunk  11 | messages    96,273,835 | book digest 9d4ff7a281bdb6e0
  checkpoint  20 | message   100,000,000 | 10:55:11.316 | resting orders 1,629,079
  checkpoint  21 | message   105,000,000 | 11:00:35.156 | resting orders 1,630,196
  chunk  12 | messages   105,138,320 | book digest 3539b159cef55427
  checkpoint  22 | message   110,000,000 | 11:04:57.847 | resting orders 1,627,768
  chunk  13 | messages   114,005,702 | book digest 13089b390423ecf2
  checkpoint  23 | message   115,000,000 | 11:10:55.101 | resting orders 1,632,730
  checkpoint  24 | message   120,000,000 | 11:16:53.860 | resting orders 1,637,947
  chunk  14 | messages   122,875,075 | book digest 1d08a678f7aee3e6
  checkpoint  25 | message   125,000,000 | 11:23:10.732 | resting orders 1,639,045
  checkpoint  26 | message   130,000,000 | 11:29:44.876 | resting orders 1,639,491
  chunk  15 | messages   131,745,852 | book digest b661faf7e007c261
  checkpoint  27 | message   135,000,000 | 11:36:21.981 | resting orders 1,639,796
  checkpoint  28 | message   140,000,000 | 11:43:12.138 | resting orders 1,640,117
  chunk  16 | messages   140,612,658 | book digest 1cab53b2d448467a
  checkpoint  29 | message   145,000,000 | 11:50:10.259 | resting orders 1,641,331
  chunk  17 | messages   149,483,905 | book digest b244fa143bbecd97
  checkpoint  30 | message   150,000,000 | 11:57:40.768 | resting orders 1,642,646
  checkpoint  31 | message   151,453,346 | 11:59:59.998 | resting orders 1,642,242
  books at 12:00:00.000 ET (state after message 151,453,346):
  AAPL   locate 14    resting 39,587 | levels bid 2711 ask 2624 | overflow levels 54 | BBO 162.3000 x 101 / 162.3100 x 400
