results/replay_20190130_causal_differential.log
=== lob_replay: NASDAQ TotalView-ITCH 5.0 day replay with ref::Market differential ===
run: 2026-09-23 10:12:05 local | cpu: Intel(R) Core(TM) Ultra 7 265H | compiler: g++ 16.1.0
command: lob_replay 01302019.NASDAQ_ITCH50 --differential --placement causal
source: git commit b8ea69f059225ae816bb683c0fb57aeade1746b6
file: 01302019.NASDAQ_ITCH50
chunk 268,435,456 bytes | checkpoint every 5,000,000 messages | ladder budget 1,024 MB | placement causal

[1] pre-scan (untimed, 187.9 s)
  bytes 11,245,883,092 | messages 368,366,634 | trailing bytes 0
  message counts by type:
     A   162,970,455    B           116    C       158,886    D   158,273,361
     E     8,096,995    F     1,725,898    H         8,805    I     3,684,511
     J            62    L       193,769    P     1,326,184    Q        17,430
     R         8,714    S             6    U    27,222,746    V             1
     X     4,669,874    Y         8,821
  bad_length 0 | unknown type 0
  first message 03:03:59.687 | last message 20:05:00.000 (ET, from message timestamps) | timestamps out of order 0
  stock directory: 8,714 'R' messages for 8,713 stock_locates (1 repeated, 0 renamed) | locates with order messages: 8,695
  adds (A, F and the add half of U): 191,919,099 | peak resting orders, whole market: 1,742,866
  add prices that are not whole cents: 718,627 | outside $0.01..$1310.72: 587,096
  sizing (18.6 s): 8,695 books | grid $0.01: 8,695, grid $0.0001: 0 | ladder 859 MB | band ticks min 2,048 median 2,048 max 2,048
  placement causal: every ladder 2,048 ticks; each book centers it on its first add and re-centers it on its midpoint after 8 near-touch misses, grid $0.01 at or above $1.00 and $0.0001 below, from the messages already applied (grids and bands above are before the first add)
  adds the ladders cover: not predicted, the ladders move
  pools 2,276,721 order slots (73 MB) | id maps 6,642,368 slots (106 MB)

  named symbols (Stock Directory, and the 'Q' crosses NASDAQ ran):
  AAPL   locate 14    adds 875,938 | peak resting 42,774 | ladder 2,048 ticks, placed by the book
         opening cross 163.2200 x 770,817 shares at 09:30:00.300
         closing cross 165.2500 x 2,340,937 shares at 16:00:00.563
  MSFT   locate 5217  adds 867,658 | peak resting 22,116 | ladder 2,048 ticks, placed by the book
         opening cross 104.6200 x 500,581 shares at 09:30:00.148
         closing cross 106.3800 x 2,606,642 shares at 16:00:00.531
  AMZN   locate 381   adds 511,215 | peak resting 39,028 | ladder 2,048 ticks, placed by the book
         opening cross 1623.0000 x 42,456 shares at 09:30:00.752
         closing cross 1670.4300 x 183,741 shares at 16:00:00.764
  BRK.A  not in this day's stock directory
  BKNG   locate 894   adds 46,197 | peak resting 1,499 | ladder 2,048 ticks, placed by the book
         opening cross 1825.3300 x 2,222 shares at 09:30:00.291
         closing cross 1818.7000 x 19,741 shares at 16:00:00.613
  WFT    locate 8401  adds 71,082 | peak resting 741 | ladder 2,048 ticks, placed by the book
         opening cross 0.0000 x 0 shares at 09:30:00.560
         closing cross 0.0000 x 0 shares at 16:00:00.427

[2] replay, differential against ref::Market after every message and in full at every checkpoint | thread pinned to cpu 2
  checkpoint   1 | message     5,000,000 | 07:50:47.762 | books 8,695 | levels 17,212 | orders 21,239 | mismatches 0
  chunk   1 | messages     9,031,559 | book digest c1909233da6bd73d
  checkpoint   2 | message    10,000,000 | 09:29:25.142 | books 8,695 | levels 197,459 | orders 340,926 | mismatches 0
  checkpoint   3 | message    15,000,000 | 09:32:23.480 | books 8,695 | levels 623,177 | orders 1,481,028 | mismatches 0
  chunk   2 | messages    16,693,204 | book digest 35ace202b2372ba5
  checkpoint   4 | message    20,000,000 | 09:36:09.034 | books 8,695 | levels 649,158 | orders 1,533,131 | mismatches 0
  checkpoint   5 | message    25,000,000 | 09:39:49.689 | books 8,695 | levels 658,319 | orders 1,556,851 | mismatches 0
  chunk   3 | messages    25,506,955 | book digest ee12c413e7aec9d7
  checkpoint   6 | message    30,000,000 | 09:43:45.424 | books 8,695 | levels 656,103 | orders 1,548,122 | mismatches 0
  chunk   4 | messages    34,337,226 | book digest e3ebf4f7728624b1
  checkpoint   7 | message    35,000,000 | 09:47:51.598 | books 8,695 | levels 654,409 | orders 1,570,457 | mismatches 0
  checkpoint   8 | message    40,000,000 | 09:52:10.696 | books 8,695 | levels 658,245 | orders 1,585,524 | mismatches 0
  chunk   5 | messages    43,178,307 | book digest c7ce2d3b7d1aef38
  checkpoint   9 | message    45,000,000 | 09:56:54.377 | books 8,695 | levels 659,668 | orders 1,589,701 | mismatches 0
  checkpoint  10 | message    50,000,000 | 10:01:44.569 | books 8,695 | levels 661,217 | orders 1,593,422 | mismatches 0
  chunk   6 | messages    52,020,225 | book digest 768d5e3b4d4aadf7
  checkpoint  11 | message    55,000,000 | 10:06:04.473 | books 8,695 | levels 663,443 | orders 1,600,015 | mismatches 0
  checkpoint  12 | message    60,000,000 | 10:11:06.173 | books 8,695 | levels 664,483 | orders 1,605,440 | mismatches 0
  chunk   7 | messages    60,871,499 | book digest edc89b1c4e7dff5c
  checkpoint  13 | message    65,000,000 | 10:15:56.915 | books 8,695 | levels 667,286 | orders 1,612,661 | mismatches 0
  chunk   8 | messages    69,718,789 | book digest 98297ac800eef764
  checkpoint  14 | message    70,000,000 | 10:21:06.736 | books 8,695 | levels 667,456 | orders 1,614,490 | mismatches 0
  checkpoint  15 | message    75,000,000 | 10:26:57.655 | books 8,695 | levels 667,861 | orders 1,615,303 | mismatches 0
  chunk   9 | messages    78,569,068 | book digest 6d80cf185da2bbdd
  checkpoint  16 | message    80,000,000 | 10:32:45.713 | books 8,695 | levels 669,032 | orders 1,613,450 | mismatches 0
  checkpoint  17 | message    85,000,000 | 10:37:51.130 | books 8,695 | levels 670,788 | orders 1,620,864 | mismatches 0
  chunk  10 | messages    87,416,025 | book digest f3b833d52eb39d77
  checkpoint  18 | message    90,000,000 | 10:43:20.184 | books 8,695 | levels 672,199 | orders 1,626,686 | mismatches 0
  checkpoint  19 | message    95,000,000 | 10:49:09.141 | books 8,695 | levels 672,821 | orders 1,629,107 | mismatches 0
  chunk  11 | messages    96,273,835 | book digest 9d4ff7a281bdb6e0
  checkpoint  20 | message   100,000,000 | 10:55:11.316 | books 8,695 | levels 673,338 | orders 1,629,079 | mismatches 0
  checkpoint  21 | message   105,000,000 | 11:00:35.156 | books 8,695 | levels 673,799 | orders 1,630,196 | mismatches 0
  chunk  12 | messages   105,138,320 | book digest 3539b159cef55427
  checkpoint  22 | message   110,000,000 | 11:04:57.847 | books 8,695 | levels 675,257 | orders 1,627,768 | mismatches 0
  chunk  13 | messages   114,005,702 | book digest 13089b390423ecf2
  checkpoint  23 | message   115,000,000 | 11:10:55.101 | books 8,695 | levels 676,318 | orders 1,632,730 | mismatches 0
  checkpoint  24 | message   120,000,000 | 11:16:53.860 | books 8,695 | levels 676,562 | orders 1,637,947 | mismatches 0
  chunk  14 | messages   122,875,075 | book digest 1d08a678f7aee3e6
  checkpoint  25 | message   125,000,000 | 11:23:10.732 | books 8,695 | levels 676,171 | orders 1,639,045 | mismatches 0
  checkpoint  26 | message   130,000,000 | 11:29:44.876 | books 8,695 | levels 676,463 | orders 1,639,491 | mismatches 0
  chunk  15 | messages   131,745,852 | book digest b661faf7e007c261
  checkpoint  27 | message   135,000,000 | 11:36:21.981 | books 8,695 | levels 676,891 | orders 1,639,796 | mismatches 0
  checkpoint  28 | message   140,000,000 | 11:43:12.138 | books 8,695 | levels 677,254 | orders 1,640,117 | mismatches 0
  chunk  16 | messages   140,612,658 | book digest 1cab53b2d448467a
  checkpoint  29 | message   145,000,000 | 11:50:10.259 | books 8,695 | levels 677,456 | orders 1,641,331 | mismatches 0
  chunk  17 | messages   149,483,905 | book digest b244fa143bbecd97
  checkpoint  30 | message   150,000,000 | 11:57:40.768 | books 8,695 | levels 677,707 | orders 1,642,646 | mismatches 0
